Workbook

Sheet Contents
A3: Specialist homelessness services 2023–24
A5: Data tables
A6: x
A7: These data tables supplement the report, Specialist homelessness services 2023–24 (AIHW 2024), and provide information on people who received assistance from specialist homelessness agencies in 2023–24, the assistance they received and their changes in housing and other circumstances. Data on those who requested services, but were not provided with support are also presented. The data are compiled from the Specialist Homelessness Services Collection (SHSC) which is collated by the AIHW. Please refer to the report for further information about the collection, and information that will help to interpret the data.
A8: Please note that there is the potential for minor revisions of data in this report. Please check the online version at <www.aihw.gov.au> for any amendments.
A10: Framework
A11: =OVERVIEW.1!A2 -> Table OVERVIEW.1: Agencies contributing support periods, by jurisdiction, 2011–12 to 2023–24
A12: =OVERVIEW.2!A2 -> Table OVERVIEW.2: Agencies by number of clients, by jurisdiction, 2023–24
A13: =OVERVIEW.3!A2 -> Table OVERVIEW.3: Clients of Specialist Homelessness Services by service type provided or referred, state and territory, 2023–24
A15: All clients
A16: ='CLIENTS.1'!A2 -> Table CLIENTS.1: Clients and support periods, by age and sex, and by state and territory, 2023–24
A17: ='CLIENTS.2'!A2 -> Table CLIENTS.2: Clients, by new and returning client status, and by state and territory, 2023–24
A18: ='CLIENTS.3'!A2 -> Table CLIENTS.3: Clients, by country of birth (country group), and by state and territory, 2023–24
A19: ='CLIENTS.4'!A2 -> Table CLIENTS.4: Clients by country of birth (top 10), and by state and territory, 2023–24
A20: ='CLIENTS.5'!A2 -> Table CLIENTS.5: Clients born overseas, by year of arrival, 2023–24
A21: ='CLIENTS.6'!A2 -> Table CLIENTS.6: Clients born overseas, by Remoteness Area, 2023–24
A22: ='CLIENTS.7'!A2 -> Table CLIENTS.7: Clients by main language spoken at home other than English (top 10), 2023–24
A23: ='CLIENTS.8'!A2 -> Table CLIENTS.8: Clients by broad group of main language spoken at home (other than English) and proficiency of spoken English, 2023–24
A24: ='CLIENTS.9'!A2 -> Table CLIENTS.9: Clients, by presenting unit type at the beginning of support, and by state and territory, 2023–24
A25: ='CLIENTS.10'!A2 -> Table CLIENTS.10: Clients, by living arrangement, and by state and territory, 2023–24
A26: ='CLIENTS.11'!A2 -> Table CLIENTS.11: Clients, by housing situation at first presentation, and by state and territory, 2023–24
A27: ='CLIENTS.12'!A2 -> Table CLIENTS.12: Clients, by homeless status at first presentation, by client groups, 2019–20 to 2023–24
A28: ='CLIENTS.13'!A2 -> Table CLIENTS.13: Clients who first presented to an agency reporting no shelter/improvised dwelling (rough sleepers), by dwelling type, 2023–24
A29: ='CLIENTS.14'!A2 -> Table CLIENTS.14: Clients, by homelessness status in the month before the first support period, by state and territory, 2023–24
A30: ='CLIENTS.15'!A2 -> Table CLIENTS.15: Clients, by source of referral at the beginning of support, and by state and territory, 2023–24
A31: ='CLIENTS.16'!A2 -> Table CLIENTS.16: Clients aged 15 and over, by main source of income, and by state and territory, 2023–24
A32: ='CLIENTS.17'!A2 -> Table CLIENTS.17: Clients by National Disability Insurance Scheme status, and by state and territory, 2023–24
A33: ='CLIENTS.18'!A2 -> Table CLIENTS.18: Clients, by educational enrolment status at beginning of support and age, and by state and territory, 2023–24
A34: ='CLIENTS.19'!A2 -> Table CLIENTS.19: Clients aged 15 or over, by labour force status, and by state and territory, 2023–24
A35: ='CLIENTS.20'!A2 -> Table CLIENTS.20: Clients, by educational enrolment status at beginning of support and labour force status, and by state and territory, 2023–24
A36: ='CLIENTS.21'!A2 -> Table CLIENTS.21: Clients, by reasons for seeking assistance, and by state and territory, 2023–24
A37: ='CLIENTS.22'!A2 -> Table CLIENTS.22: Clients, by main reasons for seeking assistance, and by state and territory, 2023–24
A38: ='CLIENTS.23'!A2 -> Table CLIENTS.23: Clients, by homeless status at first presentation and main reasons for seeking assistance, 2023–24
A39: ='CLIENTS.24'!A2 -> Table CLIENTS.24: Clients, by need for services and assistance and service provision status, and by state and territory, 2023–24
A40: ='CLIENTS.25'!A2 -> Table CLIENTS.25: Clients, by total nights of accommodation, and by state and territory, 2023–24
A41: ='CLIENTS.26'!A2 -> Table CLIENTS.26: Average amount of financial assistance provided to clients, by type of financial assistance, and by state and territory, 2023–24
A42: ='CLIENTS.27'!A2 -> Table CLIENTS.27: Clients, by number of support periods, and by state and territory, 2023–24
A43: ='CLIENTS.28'!A2 -> Table CLIENTS.28: Support periods, by indicative duration over the reporting period, and by state and territory, 2023–24
A44: ='CLIENTS.29'!A2 -> Table CLIENTS.29: Clients, by total days of support, and by state and territory, 2023–24
A45: ='CLIENTS.30'!A2 -> Table CLIENTS.30: Clients with any closed support period, by reason support period ended, and by state and territory, 2023–24
...

Sheet Explanatory notes
A1: Explanatory notes
A3: These tables relate to all clients who were assisted in the 2023–24 reporting period by specialist homelessness agencies.
A4: Further information about the Specialist Homelessness Services Collection is available in the national data report <https://www.aihw.gov.au/reports-statistics/health-welfare-services/homelessness-services/reports>.
A6: Client, support period, and presenting unit data
A7: Data presented in these tables are mainly based on 'clients', with some data based on 'support periods' or 'client groups' (or 'presenting units'—which identify clients who present together to a specialist homelessness agency, including clients who present alone—and receive a service). Information on clients who are homeless, at risk of homelessness or part of a specialist interest group, is mostly client-level data and information on agencies, unmet demand and trends data is predominantly support period data.
A8: Due to improvements in agency response and SLK validity rates, data for 2017–18 onwards were not weighted. As the aim of the imputation strategy was to account for low rates of agency response and SLK validity in previous years, unweighted data for 2017–18 onwards are directly comparable with weighted data for 2011–12 to 2016–17. Comparisons between years of counts of clients and support periods should use weighted data for 2011–12 to 2016–17 and unweighted data from 2017–18 onwards.
A10: Client-level data
A11: An individual client may have had more than one support period —either from the same agency or from a different agency. Data from individual clients who received services from different agencies and/or at different times are matched based on a statistical linkage key (SLK). All analyses based on client data include only those clients for whom full and valid SLK data (i.e. date of birth, sex, and alpha code based on selected letters of name) are available.
A12: Clients who have more than one support period during 2023–24 may present with different characteristics in these different support periods. For example, their main reason for seeking assistance may be 'family and domestic violence' in their first support period, and 'housing crisis' in the second. Where there are multiple responses to a question, some information presented is based on the client's response to the question when they first became a client of an agency in 2023–24. Other information is based on a counting methodology that analyses the client's responses and, where these are different responses, determines the response provided most often and the client's longest support period for each month in 2023–24. The methodology is conceptually based on the client's journey during the course of the 2023–24 reporting period regardless of their movement between jurisdictions. Annual client-level data presented by jurisdiction should be interpreted with caution as the information is representative of clients who presented to that jurisdiction at any time during the reporting period and may not represent the clients’ characteristics exhibited when they attended for services in that particular jurisdiction.
A13: Detailed information on how specific variables were derived can be found in the 'Technical information' page which is associated with this publication on the AIHW’s website <www.aihw.gov.au>.
A15: Data quality
A16: The 2023–24 Specialist Homelessness Services Collection Data Quality Statement is available from <http://meteor.aihw.gov.au>.
... A36: In 2016–17, the Australian Capital Territory introduced a new central intake service delivery model. In practice, this system requires agency workers to provide assistance of some kind to all presenting individuals. Therefore, caution should be used when comparing data over time and with data for other states and territories, particularly data relating to unassisted requests.

Sheet Derivation notes
A1: Derivation notes
A3: Further information about the Specialist Homelessness Services Collection is available in the national data report <https://www.aihw.gov.au/reports-statistics/health-welfare-services/homelessness-services/reports>.
A5: Clients at risk of homelessness
A6: In 2022–23, an improvement was introduced to the classification of clients at risk of homelessness. Clients with unknown tenure and an occupancy condition that is ‘other’, ‘unknown’ or ‘not applicable’ are now classified as ‘not stated’ rather than ‘at risk – other’. The change resulted in a reduction in the number of clients with an ‘at risk’ homelessness status and a corresponding increase in the number of ‘not stated’ clients. The change has been applied to all years of data in the collection meaning data is not comparable to publications released prior to September 2023.
A8: Young people presenting alone
A9: Young people are defined as any client aged 15–24 who presented to a specialist homelessness agency alone in their first support period.
A11: Children on a care and protection order
A12: A client is identified as being under a care or protection order if they are aged under 18 and have provided any of the following information in any support period (any month within the support period) during the reporting period (either the week before, at the beginning of the support period or during support).
A13: They reported that they were under a care and protection order and that they had the following care arrangements • residential care • family group home • relatives/kin/friends who are reimbursed • foster care • other home-based care (reimbursed) • relatives/kin/friends who are not reimbursed • independent living • other living arrangements • parents; or They have reported ‘Transition from foster care/child safety residential placements’ as a reason for seeking assistance, or main reason for seeking assistance.
A15: Clients leaving care
A16: A client is identified as transitioning from care arrangements if in their first support period during the reporting period (either the week before or at the beginning of the support period):Their dwelling type was recorded as: • hospital (excluding psychiatric) • psychiatric hospital or unit • disability support • rehabilitation • aged care facility; or One of their reasons for seeking assistance was: • transition from foster care/child safety residential placements • transition from other care arrangements.
A18: Clients exiting custodial arrangements
... A41: • Their dwelling type was recorded as rehabilitation • Their formal referral source to the specialist homelessness agency was a drug and alcohol service • During their support they required drug/alcohol counselling • They have been in a rehabilitation facility/institution in the last 12 months • They have reported 'problematic drug or substance abuse' or 'problematic alcohol use' as a reason for seeking assistance or main reason for seeking assistance.

Sheet OVERVIEW.1
A1: Table of contents
A2: Table OVERVIEW.1: Agencies contributing support periods, by jurisdiction, 2011–12 to 2023–24
A4: Year | B4: NSW | C4: Vic | D4: Qld | E4: WA | F4: SA | G4: Tas | H4: ACT | I4: NT | J4: Australia
A5: 2011–12 | B5: 359 | C5: 479 | D5: 226 | E5: 192 | F5: 93 | G5: 34 | H5: 44 | I5: 59 | J5: 1486
A6: 2012–13 | B6: 359 | C6: 491 | D6: 230 | E6: 193 | F6: 91 | G6: 36 | H6: 38 | I6: 64 | J6: 1502
A7: 2013–14 | B7: 354 | C7: 495 | D7: 226 | E7: 195 | F7: 92 | G7: 38 | H7: 41 | I7: 66 | J7: 1507
A8: 2014–15 | B8: 389 | C8: 495 | D8: 228 | E8: 193 | F8: 93 | G8: 45 | H8: 39 | I8: 66 | J8: 1548
A9: 2015–16 | B9: 300 | C9: 492 | D9: 230 | E9: 197 | F9: 91 | G9: 49 | H9: 37 | I9: 64 | J9: 1460
A10: 2016–17 | B10: 330 | C10: 516 | D10: 236 | E10: 189 | F10: 94 | G10: 45 | H10: 42 | I10: 66 | J10: 1518
A11: 2017–18 | B11: 331 | C11: 546 | D11: 245 | E11: 177 | F11: 92 | G11: 51 | H11: 37 | I11: 71 | J11: 1550
A12: 2018–19 | B12: 339 | C12: 569 | D12: 248 | E12: 178 | F12: 90 | G12: 49 | H12: 37 | I12: 73 | J12: 1583
A13: 2019–20 | B13: 341 | C13: 595 | D13: 258 | E13: 177 | F13: 86 | G13: 50 | H13: 43 | I13: 75 | J13: 1625
A14: 2020–21 | B14: 335 | C14: 635 | D14: 257 | E14: 201 | F14: 85 | G14: 58 | H14: 44 | I14: 83 | J14: 1698
A15: 2021–22 | B15: 332 | C15: 643 | D15: 261 | E15: 205 | F15: 71 | G15: 61 | H15: 44 | I15: 81 | J15: 1698
A16: 2022–23 | B16: 334 | C16: 655 | D16: 267 | E16: 205 | F16: 71 | G16: 66 | H16: 46 | I16: 79 | J16: 1723
A17: 2023–24 | B17: 345 | C17: 664 | D17: 290 | E17: 206 | F17: 71 | G17: 70 | H17: 47 | I17: 81 | J17: 1774
A19: Note: Count of SHSC agencies who contributed support periods during the reference year.

Sheet OVERVIEW.2
A1: Table of contents
A2: Table OVERVIEW.2: Agencies by number of clients, by jurisdiction, 2023–24
A4: Number of clients | B4: NSW | C4: Vic | D4: Qld | E4: WA | F4: SA | G4: Tas | H4: ACT | I4: NT
A5: 0 to 99 | B5: 109 | C5: 356 | D5: 151 | E5: 122 | F5: 28 | G5: 39 | H5: 33 | I5: 46
A6: 100 to 199 | B6: 98 | C6: 136 | D6: 62 | E6: 45 | F6: 12 | G6: 14 | H6: 11 | I6: 20
A7: 200 to 299 | B7: 52 | C7: 59 | D7: 28 | E7: 17 | F7: 10 | G7: 2 | H7: 2 | I7: 6
A8: 300 to 599 | B8: 55 | C8: 58 | D8: 25 | E8: 16 | F8: 12 | G8: 10 | H8: — | I8: 7
A9: 600 to 1,499 | B9: 31 | C9: 35 | D9: 20 | E9: 4 | F9: 3 | G9: 4 | H9: — | I9: 1
A10: 1,500 or more | B10: — | C10: 20 | D10: 4 | E10: 2 | F10: 6 | G10: 1 | H10: 1 | I10: 1
A11: Total | B11: 345 | C11: 664 | D11: 290 | E11: 206 | F11: 71 | G11: 70 | H11: 47 | I11: 81
A13: Note
A14: — nil or rounded to zero

Sheet OVERVIEW.3
A1: Table of contents
A2: Table OVERVIEW.3: Clients of Specialist Homelessness Services by service type provided or referred, state and territory, 2023–24
B4: Clients | C4: Clients | D4: Clients | E4: Per cent | F4: Per cent
A5: State/ territory | B5: Accommodation services | C5: Only services other than accommodation | D5: Total | E5: Accommodation services | F5: Only services other than accommodation
A6: NSW | B6: 34522 | C6: 32979 | D6: 67501 | E6: 51.1 | F6: 48.9
A7: Vic | B7: 52063 | C7: 49596 | D7: 101659 | E7: 51.2 | F7: 48.8
A8: Qld | B8: 31164 | C8: 17525 | D8: 48689 | E8: 64 | F8: 36
A9: WA | B9: 15876 | C9: 9092 | D9: 24968 | E9: 63.6 | F9: 36.4
A10: SA | B10: 8475 | C10: 10240 | D10: 18715 | E10: 45.3 | F10: 54.7
A11: Tas | B11: 5756 | C11: 884 | D11: 6640 | E11: 86.7 | F11: 13.3
A12: ACT | B12: 2632 | C12: 1370 | D12: 4002 | E12: 65.8 | F12: 34.2
A13: NT | B13: 5921 | C13: 4132 | D13: 10053 | E13: 58.9 | F13: 41.1
A15: Notes
A16: 1. Clients who were provided and/or referred any 'Accommodation provision' or 'Assistance to sustain housing tenure' in the reporting period are recorded under 'Accommodation services'.
A17: 2. Clients who were only provided and/or referred services other than accommodation services in the reporting period are recorded under 'Only services other than accommodation'.
A18: 3. Denominator: clients provided and/or referred any service.
A19: 4. Clients in 2023–24 who were not provided or referred any service: 914.

Sheet CLIENTS.1
A1: Table of contents
A2: Table CLIENTS.1: Clients and support periods, by age and sex, and by state and territory, 2023–24
D4: Males | E4: Males | F4: Females | G4: Females | H4: All clients | I4: All clients
A5: State/territory | B5: Data type | C5: Age group | D5: Number | E5: Per cent | F5: Number | G5: Per cent | H5: Number | I5: Per cent
A6: National | B6: All clients | C6: 0–9 | D6: 22215 | E6: 19.7 | F6: 21334 | G6: 12.8 | H6: 43549 | I6: 15.5
A7: National | B7: All clients | C7: 10–14 | D7: 8526 | E7: 7.6 | F7: 9203 | G7: 5.5 | H7: 17729 | I7: 6.3
A8: National | B8: All clients | C8: 15–17 | D8: 6430 | E8: 5.7 | F8: 9295 | G8: 5.6 | H8: 15725 | I8: 5.6
A9: National | B9: All clients | C9: 18–24 | D9: 12696 | E9: 11.2 | F9: 24635 | G9: 14.7 | H9: 37331 | I9: 13.3
A10: National | B10: All clients | C10: 25–34 | D10: 15816 | E10: 14 | F10: 34643 | G10: 20.7 | H10: 50459 | I10: 18
A11: National | B11: All clients | C11: 35–44 | D11: 18197 | E11: 16.1 | F11: 32381 | G11: 19.4 | H11: 50578 | I11: 18.1
A12: National | B12: All clients | C12: 45–54 | D12: 15134 | E12: 13.4 | F12: 20087 | G12: 12 | H12: 35221 | I12: 12.6
A13: National | B13: All clients | C13: 55–64 | D13: 8676 | E13: 7.7 | F13: 9577 | G13: 5.7 | H13: 18253 | I13: 6.5
A14: National | B14: All clients | C14: 65+ | D14: 5183 | E14: 4.6 | F14: 6050 | G14: 3.6 | H14: 11233 | I14: 4
A15: National | B15: All clients | C15: Total | D15: 112873 | E15: 100 | F15: 167205 | G15: 100 | H15: 280078 | I15: 100
A16: National | B16: All clients | C16: Sex as % of total | D16: 112873 | E16: 40.3 | F16: 167205 | G16: 59.7 | H16: 280078 | I16: 100
A17: National | B17: Clients (per 10,000 ERP)(a) | C17: 0–9 | D17: 138.2 | E17: . . | F17: 140.3 | G17: . . | H17: 139.2 | I17: . .
A18: National | B18: Clients (per 10,000 ERP)(a) | C18: 10–14 | D18: 100.1 | E18: . . | F18: 114.2 | G18: . . | H18: 107 | I18: . .
A19: National | B19: Clients (per 10,000 ERP)(a) | C19: 15–17 | D19: 128.6 | E19: . . | F19: 197.4 | G19: . . | H19: 161.9 | I19: . .
A20: National | B20: Clients (per 10,000 ERP)(a) | C20: 18–24 | D20: 103.5 | E20: . . | F20: 215.7 | G20: . . | H20: 157.6 | I20: . .
A21: National | B21: Clients (per 10,000 ERP)(a) | C21: 25–34 | D21: 80.6 | E21: . . | F21: 177.5 | G21: . . | H21: 128.9 | I21: . .
A22: National | B22: Clients (per 10,000 ERP)(a) | C22: 35–44 | D22: 98.7 | E22: . . | F22: 172.6 | G22: . . | H22: 135.9 | I22: . .
A23: National | B23: Clients (per 10,000 ERP)(a) | C23: 45–54 | D23: 93.1 | E23: . . | F23: 120.2 | G23: . . | H23: 106.8 | I23: . .
A24: National | B24: Clients (per 10,000 ERP)(a) | C24: 55–64 | D24: 58.3 | E24: . . | F24: 61.6 | G24: . . | H24: 60 | I24: . .
A25: National | B25: Clients (per 10,000 ERP)(a) | C25: 65+ | D25: 24.3 | E25: . . | F25: 24.9 | G25: . . | H25: 24.6 | I25: . .
A26: National | B26: Clients (per 10,000 ERP)(a) | C26: Total | D26: 85.3 | E26: . . | F26: 124.6 | G26: . . | H26: 105.1 | I26: . .
A27: National | B27: Support periods | C27: 0–9 | D27: 31047 | E27: 16.4 | F27: 29827 | G27: 10.2 | H27: 60874 | I27: 12.7
A28: National | B28: Support periods | C28: 10–14 | D28: 11523 | E28: 6.1 | F28: 12374 | G28: 4.3 | H28: 23897 | I28: 5
A29: National | B29: Support periods | C29: 15–17 | D29: 9615 | E29: 5.1 | F29: 15044 | G29: 5.2 | H29: 24659 | I29: 5.1
A30: National | B30: Support periods | C30: 18–24 | D30: 23188 | E30: 12.2 | F30: 46988 | G30: 16.1 | H30: 70176 | I30: 14.6
A31: National | B31: Support periods | C31: 25–34 | D31: 28756 | E31: 15.2 | F31: 65198 | G31: 22.4 | H31: 93954 | I31: 19.5
A32: National | B32: Support periods | C32: 35–44 | D32: 34557 | E32: 18.2 | F32: 61189 | G32: 21 | H32: 95746 | I32: 19.9
A33: National | B33: Support periods | C33: 45–54 | D33: 28467 | E33: 15 | F33: 35670 | G33: 12.3 | H33: 64137 | I33: 13.3
A34: National | B34: Support periods | C34: 55–64 | D34: 14737 | E34: 7.8 | F34: 15676 | G34: 5.4 | H34: 30413 | I34: 6.3
A35: National | B35: Support periods | C35: 65+ | D35: 7882 | E35: 4.2 | F35: 9105 | G35: 3.1 | H35: 16987 | I35: 3.5
A36: National | B36: Support periods | C36: Not stated | D36: 2070 | E36: . . | F36: 2707 | G36: . . | H36: 4777 | I36: . .
A37: National | B37: Support periods | C37: Total | D37: 191842 | E37: 100 | F37: 293778 | G37: 100 | H37: 485620 | I37: 100
A38: National | B38: Support periods | C38: Sex as % of total | D38: 191842 | E38: 39.5 | F38: 293778 | G38: 60.5 | H38: 485620 | I38: 100
A39: NSW | B39: All clients | C39: 0–9 | D39: 5564 | E39: 20.2 | F39: 5501 | G39: 13.6 | H39: 11065 | I39: 16.3
A40: NSW | B40: All clients | C40: 10–14 | D40: 2316 | E40: 8.4 | F40: 2615 | G40: 6.5 | H40: 4931 | I40: 7.3
A41: NSW | B41: All clients | C41: 15–17 | D41: 2378 | E41: 8.7 | F41: 3557 | G41: 8.8 | H41: 5935 | I41: 8.7
...

Sheet CLIENTS.2
A1: Table of contents
A2: Table CLIENTS.2: Clients, by new and returning client status, and by state and territory, 2023–24
C4: Males | D4: Males | E4: Females | F4: Females | G4: All clients | H4: All clients
A5: State/territory | B5: New or returning clients | C5: Number | D5: Per cent | E5: Number | F5: Per cent | G5: Number | H5: Per cent
A6: National | B6: New clients | C6: 43143 | D6: 38.2 | E6: 59060 | F6: 35.3 | G6: 102203 | H6: 36.5
A7: National | B7: Returning clients | C7: 69730 | D7: 61.8 | E7: 108145 | F7: 64.7 | G7: 177875 | H7: 63.5
A8: National | B8: Total | C8: 112873 | D8: 100 | E8: 167205 | F8: 100 | G8: 280078 | H8: 100
A9: NSW | B9: New clients | C9: 11428 | D9: 41.6 | E9: 15762 | F9: 39 | G9: 27190 | H9: 40
A10: NSW | B10: Returning clients | C10: 16058 | D10: 58.4 | E10: 24643 | F10: 61 | G10: 40701 | H10: 60
A11: NSW | B11: Total | C11: 27486 | D11: 100 | E11: 40405 | F11: 100 | G11: 67891 | H11: 100
A12: Vic | B12: New clients | C12: 15114 | D12: 35.6 | E12: 20073 | F12: 33.7 | G12: 35187 | H12: 34.5
A13: Vic | B13: Returning clients | C13: 27318 | D13: 64.4 | E13: 39459 | F13: 66.3 | G13: 66777 | H13: 65.5
A14: Vic | B14: Total | C14: 42432 | D14: 100 | E14: 59532 | F14: 100 | G14: 101964 | H14: 100
A15: Qld | B15: New clients | C15: 8291 | D15: 41.4 | E15: 10808 | F15: 37.5 | G15: 19099 | H15: 39.1
A16: Qld | B16: Returning clients | C16: 11712 | D16: 58.6 | E16: 18007 | F16: 62.5 | G16: 29719 | H16: 60.9
A17: Qld | B17: Total | C17: 20003 | D17: 100 | E17: 28815 | F17: 100 | G17: 48818 | H17: 100
... A32: NT | B32: Total | C32: 3378 | D32: 100 | E32: 6702 | F32: 100 | G32: 10080 | H32: 100
A34: Notes
A35: 1. New clients are defined as clients who have received a service from an SHSC agency in the financial year for the first time, having never received support in any previous year.
A36: 2. Returning clients are defined as clients who have received a service from an SHSC agency in the financial year plus at least 1 previous year since July 2011.

Sheet CLIENTS.3
A1: Table of contents
A2: Table CLIENTS.3: Clients, by country of birth (country group), and by state and territory, 2023–24
A4: State/ territory | B4: Country of birth | C4: Clients | D4: Per cent
A5: National | B5: Australia (includes External Territories) | C5: 236930 | D5: 86.6
A6: National | B6: Oceania and Antarctica | C6: 6664 | D6: 2.4
A7: National | B7: UK and Ireland | C7: 2266 | D7: 0.8
A8: National | B8: Western and Northern Europe | C8: 643 | D8: 0.2
A9: National | B9: Southern and Eastern Europe | C9: 2110 | D9: 0.8
A10: National | B10: North Africa and the Middle East | C10: 6969 | D10: 2.5
A11: National | B11: South-East Asia | C11: 4835 | D11: 1.8
A12: National | B12: North-East Asia | C12: 1650 | D12: 0.6
A13: National | B13: Southern and Central Asia | C13: 4994 | D13: 1.8
A14: National | B14: Northern America | C14: 567 | D14: 0.2
A15: National | B15: South and Central America and Carribean | C15: 1045 | D15: 0.4
A16: National | B16: Sub-Saharan Africa | C16: 5041 | D16: 1.8
A17: National | B17: Not stated | C17: 6364 | D17: . .
A18: National | B18: Total | C18: 280078 | D18: 100
A19: NSW | B19: Australia (includes External Territories) | C19: 58717 | D19: 88.4
A20: NSW | B20: Oceania and Antarctica | C20: 1544 | D20: 2.3
A21: NSW | B21: UK and Ireland | C21: 463 | D21: 0.7
A22: NSW | B22: Western and Northern Europe | C22: 167 | D22: 0.3
A23: NSW | B23: Southern and Eastern Europe | C23: 456 | D23: 0.7
A24: NSW | B24: North Africa and the Middle East | C24: 1612 | D24: 2.4
A25: NSW | B25: South-East Asia | C25: 1048 | D25: 1.6
A26: NSW | B26: North-East Asia | C26: 478 | D26: 0.7
A27: NSW | B27: Southern and Central Asia | C27: 895 | D27: 1.3
A28: NSW | B28: Northern America | C28: 156 | D28: 0.2
A29: NSW | B29: South and Central America and Carribean | C29: 305 | D29: 0.5
A30: NSW | B30: Sub-Saharan Africa | C30: 556 | D30: 0.8
A31: NSW | B31: Not stated | C31: 1494 | D31: . .
A32: NSW | B32: Total | C32: 67891 | D32: 100
A33: Vic | B33: Australia (includes External Territories) | C33: 81005 | D33: 81.6
A34: Vic | B34: Oceania and Antarctica | C34: 2379 | D34: 2.4
A35: Vic | B35: UK and Ireland | C35: 825 | D35: 0.8
A36: Vic | B36: Western and Northern Europe | C36: 259 | D36: 0.3
A37: Vic | B37: Southern and Eastern Europe | C37: 1138 | D37: 1.1
A38: Vic | B38: North Africa and the Middle East | C38: 4113 | D38: 4.1
A39: Vic | B39: South-East Asia | C39: 2463 | D39: 2.5
A40: Vic | B40: North-East Asia | C40: 702 | D40: 0.7
A41: Vic | B41: Southern and Central Asia | C41: 2968 | D41: 3
...

Sheet CLIENTS.4
A1: Table of contents
A2: Table CLIENTS.4: Clients by country of birth (top 10), and by state and territory, 2023–24
A4: State/ territory | B4: Country of birth | C4: Clients | D4: Per cent
A5: National | B5: Australia | C5: 236810 | D5: 86.5
A6: National | B6: New Zealand | C6: 4543 | D6: 1.7
A7: National | B7: England | C7: 1727 | D7: 0.6
A8: National | B8: India | C8: 1620 | D8: 0.6
A9: National | B9: Afghanistan | C9: 1563 | D9: 0.6
A10: National | B10: Sudan | C10: 1461 | D10: 0.5
A11: National | B11: Philippines | C11: 1361 | D11: 0.5
A12: National | B12: Iran | C12: 1242 | D12: 0.5
A13: National | B13: Vietnam | C13: 1030 | D13: 0.4
A14: National | B14: China (excludes SARs(a) and Taiwan) | C14: 1030 | D14: 0.4
A15: National | B15: Others | C15: 21327 | D15: 7.8
A16: National | B16: Not stated | C16: 6364 | D16: . .
A17: National | B17: Total clients | C17: 280078 | D17: 100
A18: NSW | B18: Australia | C18: 58685 | D18: 88.4
A19: NSW | B19: New Zealand | C19: 955 | D19: 1.4
A20: NSW | B20: Philippines | C20: 402 | D20: 0.6
A21: NSW | B21: England | C21: 341 | D21: 0.5
A22: NSW | B22: Lebanon | C22: 340 | D22: 0.5
A23: NSW | B23: Iraq | C23: 274 | D23: 0.4
A24: NSW | B24: Afghanistan | C24: 273 | D24: 0.4
A25: NSW | B25: Iran | C25: 273 | D25: 0.4
A26: NSW | B26: China (excludes SARs(a) and Taiwan) | C26: 263 | D26: 0.4
A27: NSW | B27: Fiji | C27: 253 | D27: 0.4
A28: NSW | B28: Others | C28: 4338 | D28: 6.5
A29: NSW | B29: Not stated | C29: 1494 | D29: . .
A30: NSW | B30: Total clients | C30: 67891 | D30: 100
A31: Vic | B31: Australia | C31: 80984 | D31: 81.6
A32: Vic | B32: New Zealand | C32: 1704 | D32: 1.7
A33: Vic | B33: India | C33: 1000 | D33: 1
A34: Vic | B34: Sudan | C34: 995 | D34: 1
A35: Vic | B35: Afghanistan | C35: 970 | D35: 1
A36: Vic | B36: Iran | C36: 729 | D36: 0.7
A37: Vic | B37: Ethiopia | C37: 694 | D37: 0.7
A38: Vic | B38: Vietnam | C38: 672 | D38: 0.7
A39: Vic | B39: England | C39: 618 | D39: 0.6
A40: Vic | B40: Somalia | C40: 585 | D40: 0.6
A41: Vic | B41: Others | C41: 10337 | D41: 10.4
...

Sheet CLIENTS.5
A1: Table of contents
A2: Table CLIENTS.5: Clients born overseas, by year of arrival, 2023–24
A4: Year of arrival | B4: Number | C4: Per cent
A5: 2020 – 2024 | B5: 4558 | C5: 16.1
A6: 2015 – 2019 | B6: 5413 | C6: 19.1
A7: 2014 or before | B7: 18398 | C7: 64.9
A8: Not stated | B8: 8415 | C8: . .
A9: Total | B9: 36784 | C9: 100
A11: Notes
A12: 1. Excludes clients whose country of birth was Australia (including External Territories) or whose country of birth was not stated.
A13: 2. Per cent calculations based on total clients less 'Not stated'.
A14: . . not applicable

Sheet CLIENTS.6
A1: Table of contents
A2: Table CLIENTS.6: Clients born overseas, by Remoteness Area, 2023–24
A4: Remoteness Area | B4: Number | C4: Per cent
A5: Major cities | B5: 32072 | C5: 87.2
A6: Inner regional | B6: 3067 | C6: 8.3
A7: Outer regional | B7: 1417 | C7: 3.9
A8: Remote | B8: 171 | C8: 0.5
A9: Very remote | B9: 57 | C9: 0.2
A10: Total | B10: 36784 | C10: 100
A12: Notes
A13: 1. Remoteness Area is assigned using the Australian Bureau of Statistics classification, Australian Statistical Geography Standard (ASGS), 2021.
A14: 2. Agencies participating in the SHSC are assigned to a Statistical Area 2 (SA2) based on their postcode, suburb, and state. SA2 is then mapped to Remoteness Area using a second concordance. Clients are assigned a Remoteness Area based on the SHS agency where they first sought support.
A15: 3. Excludes clients whose country of birth was Australia (including External Territories) or whose country of birth was not stated.

Sheet CLIENTS.7
A1: Table of contents
A2: Table CLIENTS.7: Clients by main language spoken at home other than English (top 10), 2023–24
A4: Main language spoken at home | B4: Number | C4: Per cent
A5: Aboriginal English so described | B5: 8910 | C5: 21.3
A6: Arabic | B6: 4641 | C6: 11.1
A7: Persian (excluding Dari) | B7: 1141 | C7: 2.7
A8: Dari | B8: 1116 | C8: 2.7
A9: Vietnamese | B9: 1102 | C9: 2.6
A10: Somali | B10: 1040 | C10: 2.5
A11: Mandarin | B11: 922 | C11: 2.2
A12: Spanish | B12: 859 | C12: 2.1
A13: Dinka | B13: 846 | C13: 2
A14: Other Australian Indigenous Languages nec | B14: 788 | C14: 1.9
A15: Northern European Languages (excluding English) (balance of) | B15: 408 | C15: 1
A16: Southern European Languages (balance of) | B16: 1331 | C16: 3.2
... A24: Other Languages (excluding African Languages)(b) | B24: 2114 | C24: 5
A25: English only | B25: 223163 | C25: . .
A26: Not stated | B26: 13614 | C26: . .
A27: Total | B27: 278676 | C27: 100
A29: (a) 'African Languages' is a narrow group classification of languages under the broad group 'Other Languages'.
A30: (b) 'Other Languages (excluding African Languages)' includes all other narrow groups under the broad group 'Other Languages'.
A31: Notes
A32: 1. Languages and broad groups of languages are based on the Australian Standard Classification of Languages (ASCL), 2016 (ABS Catalogue 1267.0).
A33: 2. The top 10 main languages spoken at home other than English are listed in descending order.
A34: 3. 'Balance of' refers to the remainder of languages in the broad groups excluding those already listed in the top 10.
A35: 4. Percentages are calculated using total clients excluding those whose main language spoken at home was not stated or English only.
A36: 5. Excludes 1,402 clients who only had support period(s) starting before 1 July 2019.
A37: . . not applicable

Sheet CLIENTS.8
A1: Table of contents
A2: Table CLIENTS.8: Clients by broad group of main language spoken at home (other than English) and proficiency of spoken English, 2023–24
A4: Data type | B4: Main language other than English spoken at home | C4: Very well | D4: Well | E4: Not well | F4: Not at all | G4: Not stated
A5: Number | B5: Northern European Languages (excluding English) | C5: 276 | D5: 79 | E5: 10 | F5: 31 | G5: —
A6: Number | B6: Southern European Languages | C6: 1099 | D6: 561 | E6: 240 | F6: 51 | G6: 149
A7: Number | B7: Eastern European Languages | C7: 596 | D7: 329 | E7: 156 | F7: 56 | G7: 78
A8: Number | B8: Southwest And Central Asian Languages | C8: 2219 | D8: 2167 | E8: 1776 | F8: 653 | G8: 904
A9: Number | B9: Southern Asian Languages | C9: 1001 | D9: 1069 | E9: 356 | F9: 55 | G9: 219
A10: Number | B10: Southeast Asian Languages | C10: 1054 | D10: 1242 | E10: 814 | F10: 213 | G10: 394
A11: Number | B11: Eastern Asian Languages | C11: 423 | D11: 554 | E11: 467 | F11: 193 | G11: 145
A12: Number | B12: Australian Indigenous Languages | C12: 3974 | D12: 7967 | E12: 469 | F12: 42 | G12: 612
A13: Number | B13: African Languages(a) | C13: 1363 | D13: 1432 | E13: 726 | F13: 217 | G13: 406
A14: Number | B14: Other Languages (excluding African Languages)(b) | C14: 1029 | D14: 609 | E14: 110 | F14: 35 | G14: 167
A15: Per cent | B15: Northern European Languages (excluding English) | C15: 69.7 | D15: 19.9 | E15: 2.5 | F15: 7.8 | G15: . .
A16: Per cent | B16: Southern European Languages | C16: 56.3 | D16: 28.8 | E16: 12.3 | F16: 2.6 | G16: . .
A17: Per cent | B17: Eastern European Languages | C17: 52.4 | D17: 28.9 | E17: 13.7 | F17: 4.9 | G17: . .
A18: Per cent | B18: Southwest And Central Asian Languages | C18: 32.6 | D18: 31.8 | E18: 26.1 | F18: 9.6 | G18: . .
A19: Per cent | B19: Southern Asian Languages | C19: 40.3 | D19: 43.1 | E19: 14.3 | F19: 2.2 | G19: . .
A20: Per cent | B20: Southeast Asian Languages | C20: 31.7 | D20: 37.4 | E20: 24.5 | F20: 6.4 | G20: . .
A21: Per cent | B21: Eastern Asian Languages | C21: 25.8 | D21: 33.8 | E21: 28.5 | F21: 11.8 | G21: . .
A22: Per cent | B22: Australian Indigenous Languages | C22: 31.9 | D22: 64 | E22: 3.8 | F22: 0.3 | G22: . .
A23: Per cent | B23: African Languages(a) | C23: 36.5 | D23: 38.3 | E23: 19.4 | F23: 5.8 | G23: . .
A24: Per cent | B24: Other Languages (excluding African Languages)(b) | C24: 57.7 | D24: 34.2 | E24: 6.2 | F24: 2 | G24: . .
A26: (a) 'African Languages' is a narrow group classification of languages under the broad group 'Other Languages'.
A27: (b) 'Other Languages (excluding African Languages)' includes all other narrow groups under the broad group 'Other Languages'.
A28: Notes
A29: 1. Broad groups of languages are based on the Australian Standard Classification of Languages (ASCL), 2016 (ABS Catalogue 1267.0).
A30: 2. Percentages are calculated using clients by broad language group as the denominator, excluding those whose proficiency in spoken English was not stated.
A31: 3. Excludes 1,402 clients who only had support period(s) starting before 1 July 2019.
A32: 4. Excludes clients whose main language spoken at home was English or who were under 5 years of age.
A33: . . not applicable

Sheet CLIENTS.9
A1: Table of contents
A2: Table CLIENTS.9: Clients, by presenting unit type at the beginning of support, and by state and territory, 2023–24
A4: State/territory | B4: Presenting unit type | C4: Number | D4: Per cent
A5: National | B5: Alone/not part of family | C5: 177806 | D5: 63.5
A6: National | B6: Couple with child/ren | C6: 12448 | D6: 4.4
A7: National | B7: Single with child/ren | C7: 80027 | D7: 28.6
A8: National | B8: Couple without children | C8: 5652 | D8: 2
A9: National | B9: Other family group | C9: 2154 | D9: 0.8
A10: National | B10: Other group | C10: 1991 | D10: 0.7
A11: National | B11: Total | C11: 280078 | D11: 100
A12: NSW | B12: Alone/not part of family | C12: 42012 | D12: 61.9
A13: NSW | B13: Couple with child/ren | C13: 2536 | D13: 3.7
A14: NSW | B14: Single with child/ren | C14: 21213 | D14: 31.2
A15: NSW | B15: Couple without children | C15: 1234 | D15: 1.8
A16: NSW | B16: Other family group | C16: 550 | D16: 0.8
... A67: NT | B67: Total | C67: 10080 | D67: 100
A69: Notes
A70: 1. The presenting unit type at the beginning of support. This data item indicates the group of people with whom the client presents to the Specialist Homelessness Services agency. After identifying the presenting unit head, the client identifies the relationship to that unit head.
A71: 2. For data quality issues, refer to the Explanatory Notes.

Sheet CLIENTS.10
A1: Table of contents
A2: Table CLIENTS.10: Clients, by living arrangement, and by state and territory, 2023–24
C4: Males | D4: Males | E4: Females | F4: Females | G4: All clients | H4: All clients
A5: State/territory | B5: Living Arrangement | C5: Number | D5: Per cent | E5: Number | F5: Per cent | G5: Number | H5: Per cent
A6: National | B6: Lone person | C6: 48122 | D6: 44.3 | E6: 42842 | F6: 26.7 | G6: 90964 | H6: 33.8
A7: National | B7: One parent with child/ren | C7: 26689 | D7: 24.6 | E7: 65630 | F7: 40.9 | G7: 92319 | H7: 34.3
A8: National | B8: Couple with child/ren | C8: 10839 | D8: 10 | E8: 16974 | F8: 10.6 | G8: 27813 | H8: 10.3
A9: National | B9: Couple without child/ren | C9: 4723 | D9: 4.4 | E9: 7337 | F9: 4.6 | G9: 12060 | H9: 4.5
A10: National | B10: Other family | C10: 12198 | D10: 11.2 | E10: 20045 | F10: 12.5 | G10: 32243 | H10: 12
A11: National | B11: Group | C11: 5985 | D11: 5.5 | E11: 7648 | F11: 4.8 | G11: 13633 | H11: 5.1
A12: National | B12: Not stated | C12: 4317 | D12: . . | E12: 6729 | F12: . . | G12: 11046 | H12: . .
A13: National | B13: Total | C13: 112873 | D13: 100 | E13: 167205 | F13: 100 | G13: 280078 | H13: 100
A14: NSW | B14: Lone person | C14: 12165 | D14: 46.5 | E14: 11931 | F14: 30.4 | G14: 24096 | H14: 36.9
A15: NSW | B15: One parent with child/ren | C15: 6918 | D15: 26.5 | E15: 16329 | F15: 41.7 | G15: 23247 | H15: 35.6
A16: NSW | B16: Couple with child/ren | C16: 2445 | D16: 9.4 | E16: 3647 | F16: 9.3 | G16: 6092 | H16: 9.3
A17: NSW | B17: Couple without child/ren | C17: 1089 | D17: 4.2 | E17: 1661 | F17: 4.2 | G17: 2750 | H17: 4.2
A18: NSW | B18: Other family | C18: 2435 | D18: 9.3 | E18: 4091 | F18: 10.4 | G18: 6526 | H18: 10
A19: NSW | B19: Group | C19: 1082 | D19: 4.1 | E19: 1529 | F19: 3.9 | G19: 2611 | H19: 4
A20: NSW | B20: Not stated | C20: 1352 | D20: . . | E20: 1217 | F20: . . | G20: 2569 | H20: . .
A21: NSW | B21: Total | C21: 27486 | D21: 100 | E21: 40405 | F21: 100 | G21: 67891 | H21: 100
A22: Vic | B22: Lone person | C22: 18856 | D22: 46.5 | E22: 14949 | F22: 26.8 | G22: 33805 | H22: 35.1
A23: Vic | B23: One parent with child/ren | C23: 9395 | D23: 23.2 | E23: 23237 | F23: 41.6 | G23: 32632 | H23: 33.8
A24: Vic | B24: Couple with child/ren | C24: 3703 | D24: 9.1 | E24: 5746 | F24: 10.3 | G24: 9449 | H24: 9.8
A25: Vic | B25: Couple without child/ren | C25: 1853 | D25: 4.6 | E25: 2737 | F25: 4.9 | G25: 4590 | H25: 4.8
A26: Vic | B26: Other family | C26: 4248 | D26: 10.5 | E26: 6439 | F26: 11.5 | G26: 10687 | H26: 11.1
A27: Vic | B27: Group | C27: 2503 | D27: 6.2 | E27: 2737 | F27: 4.9 | G27: 5240 | H27: 5.4
A28: Vic | B28: Not stated | C28: 1874 | D28: . . | E28: 3687 | F28: . . | G28: 5561 | H28: . .
A29: Vic | B29: Total | C29: 42432 | D29: 100 | E29: 59532 | F29: 100 | G29: 101964 | H29: 100
A30: Qld | B30: Lone person | C30: 8133 | D30: 41.6 | E30: 7164 | F30: 25.4 | G30: 15297 | H30: 32.1
A31: Qld | B31: One parent with child/ren | C31: 5656 | D31: 28.9 | E31: 12903 | F31: 45.8 | G31: 18559 | H31: 38.9
A32: Qld | B32: Couple with child/ren | C32: 2421 | D32: 12.4 | E32: 3195 | F32: 11.3 | G32: 5616 | H32: 11.8
A33: Qld | B33: Couple without child/ren | C33: 881 | D33: 4.5 | E33: 1158 | F33: 4.1 | G33: 2039 | H33: 4.3
A34: Qld | B34: Other family | C34: 1702 | D34: 8.7 | E34: 2669 | F34: 9.5 | G34: 4371 | H34: 9.2
A35: Qld | B35: Group | C35: 776 | D35: 4 | E35: 1065 | F35: 3.8 | G35: 1841 | H35: 3.9
A36: Qld | B36: Not stated | C36: 434 | D36: . . | E36: 661 | F36: . . | G36: 1095 | H36: . .
A37: Qld | B37: Total | C37: 20003 | D37: 100 | E37: 28815 | F37: 100 | G37: 48818 | H37: 100
A38: WA | B38: Lone person | C38: 2618 | D38: 32.3 | E38: 3151 | F38: 19.8 | G38: 5769 | H38: 24.1
A39: WA | B39: One parent with child/ren | C39: 1924 | D39: 23.7 | E39: 6165 | F39: 38.8 | G39: 8089 | H39: 33.7
A40: WA | B40: Couple with child/ren | C40: 843 | D40: 10.4 | E40: 1801 | F40: 11.3 | G40: 2644 | H40: 11
A41: WA | B41: Couple without child/ren | C41: 316 | D41: 3.9 | E41: 712 | F41: 4.5 | G41: 1028 | H41: 4.3
...

Sheet CLIENTS.11
A1: Table of contents
A2: Table CLIENTS.11: Clients, by housing situation at first presentation, and by state and territory, 2023–24
A4: State/territory | B4: Homeless/At risk | C4: Housing situation | D4: Males | E4: Females | F4: All clients (number) | G4: All clients (per cent)
A5: National | B5: Homeless | C5: Homeless | G5: 47.6
A6: National | B6: Homeless | C6: No shelter or improvised/inadequate dwelling | D6: 18836 | E6: 12385 | F6: 31221 | G6: 11.1
A7: National | B7: Homeless | C7: Short-term temporary accommodation | D7: 22829 | E7: 28961 | F7: 51790 | G7: 18.5
A8: National | B8: Homeless | C8: House, townhouse or flat — couch surfer or with no tenure | D8: 16044 | E8: 24494 | F8: 40538 | G8: 14.5
A9: National | B9: Homeless | C9: Other | D9: 850 | E9: 882 | F9: 1732 | G9: 0.6
A10: National | B10: At risk | C10: At risk | G10: 52.4
A11: National | B11: At risk | C11: Public or community housing — renter or rent free | D11: 12298 | E11: 24713 | F11: 37011 | G11: 13.2
A12: National | B12: At risk | C12: Private or other housing — renter, rent free or owner | D12: 29073 | E12: 60018 | F12: 89091 | G12: 31.8
A13: National | B13: At risk | C13: Institutional settings | D13: 6393 | E13: 2538 | F13: 8931 | G13: 3.2
A14: National | B14: At risk | C14: Other | D14: 1138 | E14: 1974 | F14: 3112 | G14: 1.1
A15: National | B15: Not stated | C15: Not stated | D15: 5412 | E15: 11240 | F15: 16652 | G15: 5.9
A16: National | B16: Total | C16: Total | D16: 112873 | E16: 167205 | F16: 280078 | G16: 100
A17: NSW | B17: Homeless | C17: Homeless | G17: 52.6
A18: NSW | B18: Homeless | C18: No shelter or improvised/inadequate dwelling | D18: 3369 | E18: 2063 | F18: 5432 | G18: 8
A19: NSW | B19: Homeless | C19: Short-term temporary accommodation | D19: 8185 | E19: 9711 | F19: 17896 | G19: 26.4
A20: NSW | B20: Homeless | C20: House, townhouse or flat — couch surfer or with no tenure | D20: 4079 | E20: 6423 | F20: 10502 | G20: 15.5
A21: NSW | B21: Homeless | C21: Other | D21: 137 | E21: 131 | F21: 268 | G21: 0.4
A22: NSW | B22: At risk | C22: At risk | G22: 47.4
A23: NSW | B23: At risk | C23: Public or community housing — renter or rent free | D23: 2709 | E23: 4993 | F23: 7702 | G23: 11.3
A24: NSW | B24: At risk | C24: Private or other housing — renter, rent free or owner | D24: 6736 | E24: 14206 | F24: 20942 | G24: 30.8
A25: NSW | B25: At risk | C25: Institutional settings | D25: 791 | E25: 637 | F25: 1428 | G25: 2.1
A26: NSW | B26: At risk | C26: Other | D26: 271 | E26: 386 | F26: 657 | G26: 1
A27: NSW | B27: Not stated | C27: Not stated | D27: 1209 | E27: 1855 | F27: 3064 | G27: 4.5
A28: NSW | B28: Total | C28: Total | D28: 27486 | E28: 40405 | F28: 67891 | G28: 100
A29: Vic | B29: Homeless | C29: Homeless | G29: 40.4
A30: Vic | B30: Homeless | C30: No shelter or improvised/inadequate dwelling | D30: 6318 | E30: 3421 | F30: 9739 | G30: 9.6
A31: Vic | B31: Homeless | C31: Short-term temporary accommodation | D31: 6597 | E31: 7922 | F31: 14519 | G31: 14.2
A32: Vic | B32: Homeless | C32: House, townhouse or flat — couch surfer or with no tenure | D32: 5389 | E32: 7086 | F32: 12475 | G32: 12.2
A33: Vic | B33: Homeless | C33: Other | D33: 339 | E33: 298 | F33: 637 | G33: 0.6
A34: Vic | B34: At risk | C34: At risk | G34: 59.6
A35: Vic | B35: At risk | C35: Public or community housing — renter or rent free | D35: 3256 | E35: 6053 | F35: 9309 | G35: 9.1
A36: Vic | B36: At risk | C36: Private or other housing — renter, rent free or owner | D36: 13038 | E36: 26324 | F36: 39362 | G36: 38.6
A37: Vic | B37: At risk | C37: Institutional settings | D37: 4282 | E37: 999 | F37: 5281 | G37: 5.2
A38: Vic | B38: At risk | C38: Other | D38: 410 | E38: 785 | F38: 1195 | G38: 1.2
A39: Vic | B39: Not stated | C39: Not stated | D39: 2803 | E39: 6644 | F39: 9447 | G39: 9.3
A40: Vic | B40: Total | C40: Total | D40: 42432 | E40: 59532 | F40: 101964 | G40: 100
A41: Qld | B41: Homeless | C41: Homeless | G41: 55.8
...

Sheet CLIENTS.12
A1: Table of contents
A2: Table CLIENTS.12: Clients, by homeless status at first presentation, by client groups, 2019–20 to 2023–24
A4: Data type | B4: Client group | C4: Homeless status first reported | D4: 2019–20 | E4: 2020–21 | F4: 2021–22 | G4: 2022–23 | H4: 2023–24
A5: Number | B5: All clients | C5: Homeless | D5: 116934 | E5: 114463 | F5: 113815 | G5: 119909 | H5: 125281
A6: Number | B6: All clients | C6: At risk | D6: 144303 | E6: 136553 | F6: 134468 | G6: 133992 | H6: 138145
A7: Number | B7: Indigenous clients | C7: Homeless | D7: 31538 | E7: 33374 | F7: 33199 | G7: 35226 | H7: 38290
A8: Number | B8: Indigenous clients | C8: At risk | D8: 35413 | E8: 35693 | F8: 35564 | G8: 35141 | H8: 36577
A9: Number | B9: Young people presenting alone | C9: Homeless | D9: 20430 | E9: 20462 | F9: 19599 | G9: 19839 | H9: 20577
A10: Number | B10: Young people presenting alone | C10: At risk | D10: 17632 | E10: 17390 | F10: 16415 | G10: 15939 | H10: 15525
A11: Number | B11: Children on a care and protection order | C11: Homeless | D11: 4056 | E11: 4013 | F11: 3850 | G11: 3880 | H11: 4206
A12: Number | B12: Children on a care and protection order | C12: At risk | D12: 4384 | E12: 3944 | F12: 3709 | G12: 3645 | H12: 3714
A13: Number | B13: Clients leaving care | C13: Homeless | D13: 1826 | E13: 1723 | F13: 1686 | G13: 1675 | H13: 1649
A14: Number | B14: Clients leaving care | C14: At risk | D14: 4799 | E14: 4510 | F14: 4235 | G14: 4360 | H14: 4473
A15: Number | B15: Clients exiting custodial arrangements | C15: Homeless | D15: 3126 | E15: 3105 | F15: 2940 | G15: 2732 | H15: 2666
A16: Number | B16: Clients exiting custodial arrangements | C16: At risk | D16: 6171 | E16: 5638 | F16: 5899 | G16: 6212 | H16: 6073
... A68: Per cent | B68: Clients in Remote/Very remote areas | C68: At risk | D68: 69.3 | E68: 69.5 | F68: 70.2 | G68: 68.3 | H68: 61.6
A70: Notes
A71: 1. Clients are considered to be homeless if they are living in any of the following circumstances: • No shelter or improvised dwelling: includes where dwelling type is no dwelling/street/park/in the open, motor vehicle, improvised building/dwelling, caravan, cabin, boat or tent; or tenure type is renting or living rent-free in a caravan park. • Short-term temporary accommodation: dwelling type is boarding/rooming house, emergency accommodation, hotel/motel/bed and breakfast; or tenure type is renting or living rent-free in boarding/rooming house, renting or living rent-free in emergency accommodation, or renting or living rent-free in transitional housing. • House, townhouse or flat (couch surfing or with no tenure): dwelling type is House/townhouse/flat, and tenure type is no tenure or conditions of occupancy is couch surfing.
A72: 2. Clients are considered to be at risk of homelessness if they are living in any of the following circumstances: • Public or community housing (renter or rent free): dwelling type is house/townhouse/flat and tenure type is renter or rent-free in public housing, or renter or rent-free in community housing. • Private or other housing (renter, rent-free or owner): dwelling type is house/townhouse/flat and tenure type is renter or rent free in private housing, life tenure scheme, owner-shared equity or rent/buy scheme, owner-being purchased/with mortgage, owner-fully owned, or other renter or rent free. • Institutional settings: dwelling type is hospital, psychiatric hospital/unit, disability support, rehabilitation, boarding school/residential college, adult correctional facility, youth/juvenile justice correctional centre, aged care facility or immigration detention centre.
A73: 3. The denominator for the proportions exclude clients whose homeless status at first presentation was not stated.

Sheet CLIENTS.13
A1: Table of contents
A2: Table CLIENTS.13: Clients who first presented to an agency reporting no shelter/improvised dwelling (rough sleepers), by dwelling type, 2023–24
A4: Dwelling type | B4: Number | C4: Per cent
A5: House/townhouse/flat | B5: 68 | C5: 0.2
A6: Caravan | B6: 3368 | C6: 10.8
A7: Tent | B7: 2548 | C7: 8.2
A8: Cabin | B8: 1064 | C8: 3.4
A9: Boat | B9: 85 | C9: 0.3
A10: Improvised building/dwelling | B10: 1889 | C10: 6.1
A11: No dwelling/street/park/in the open | B11: 15393 | C11: 49.3
A12: Motor vehicle | B12: 6727 | C12: 21.6
A13: Emergency accommodation | B13: 37 | C13: 0.1
A14: Hotel/motel/bed and breakfast | B14: 1 | C14: 0
A15: Other | B15: 21 | C15: 0.1
A16: Not stated | B16: 20 | C16: . .
A17: Total | B17: 31221 | C17: 100
A19: Notes
A20: 1. Rough sleeper: clients with the housing situation 'No shelter or improvised/inadequate dwelling' at the beginning of their first support period.
A21: 2. Per cent calculations based on total clients less 'Not stated'.
A22: . . not applicable

Sheet CLIENTS.14
A1: Table of contents
A2: Table CLIENTS.14: Clients, by homelessness status in the month before the first support period, by state and territory, 2023–24
A4: State/ territory | B4: Homelessness status in the month before the client's first support period | C4: Number | D4: Per cent
A5: National | B5: Homeless in previous month | C5: 113531 | D5: 42.4
A6: National | B6: Sleeping rough or in non-conventional accommodation | C6: 50284 | D6: 18.8
A7: National | B7: Short-term or emergency accommodation, due to a lack of other options | C7: 63247 | D7: 23.6
A8: National | B8: Not homeless in previous month | C8: 154139 | D8: 57.6
A9: National | B9: Not stated | C9: 12408 | D9: . .
A10: National | B10: Total | C10: 280078 | D10: 100
A11: NSW | B11: Homeless in previous month | C11: 32268 | D11: 49.8
A12: NSW | B12: Sleeping rough or in non-conventional accommodation | C12: 12349 | D12: 19.1
A13: NSW | B13: Short-term or emergency accommodation, due to a lack of other options | C13: 19919 | D13: 30.8
A14: NSW | B14: Not homeless in previous month | C14: 32466 | D14: 50.2
A15: NSW | B15: Not stated | C15: 3157 | D15: . .
A16: NSW | B16: Total | C16: 67891 | D16: 100
A17: Vic | B17: Homeless in previous month | C17: 31101 | D17: 32.3
A18: Vic | B18: Sleeping rough or in non-conventional accommodation | C18: 12684 | D18: 13.2
A19: Vic | B19: Short-term or emergency accommodation, due to a lack of other options | C19: 18417 | D19: 19.1
A20: Vic | B20: Not homeless in previous month | C20: 65199 | D20: 67.7
A21: Vic | B21: Not stated | C21: 5664 | D21: . .
A22: Vic | B22: Total | C22: 101964 | D22: 100
A23: Qld | B23: Homeless in previous month | C23: 24289 | D23: 51.1
A24: Qld | B24: Sleeping rough or in non-conventional accommodation | C24: 11899 | D24: 25.1
A25: Qld | B25: Short-term or emergency accommodation, due to a lack of other options | C25: 12390 | D25: 26.1
A26: Qld | B26: Not homeless in previous month | C26: 23209 | D26: 48.9
A27: Qld | B27: Not stated | C27: 1320 | D27: . .
A28: Qld | B28: Total | C28: 48818 | D28: 100
A29: WA | B29: Homeless in previous month | C29: 8596 | D29: 36
A30: WA | B30: Sleeping rough or in non-conventional accommodation | C30: 4439 | D30: 18.6
A31: WA | B31: Short-term or emergency accommodation, due to a lack of other options | C31: 4157 | D31: 17.4
A32: WA | B32: Not homeless in previous month | C32: 15294 | D32: 64
A33: WA | B33: Not stated | C33: 1103 | D33: . .
A34: WA | B34: Total | C34: 24993 | D34: 100
A35: SA | B35: Homeless in previous month | C35: 9218 | D35: 50.8
A36: SA | B36: Sleeping rough or in non-conventional accommodation | C36: 4631 | D36: 25.5
A37: SA | B37: Short-term or emergency accommodation, due to a lack of other options | C37: 4587 | D37: 25.3
A38: SA | B38: Not homeless in previous month | C38: 8932 | D38: 49.2
A39: SA | B39: Not stated | C39: 567 | D39: . .
A40: SA | B40: Total | C40: 18717 | D40: 100
A41: Tas | B41: Homeless in previous month | C41: 3714 | D41: 56.4
...

Sheet CLIENTS.15
A1: Table of contents
A2: Table CLIENTS.15: Clients, by source of referral at the beginning of support, and by state and territory, 2023–24
C4: Males | D4: Males | E4: Females | F4: Females | G4: All clients | H4: All clients
A5: State/territory | B5: Formal referral source | C5: Number | D5: Per cent | E5: Number | F5: Per cent | G5: Number | H5: Per cent
A6: National | B6: Specialist Homelessness Agency/outreach worker | C6: 18817 | D6: 16.8 | E6: 24580 | F6: 14.8 | G6: 43397 | H6: 15.6
A7: National | B7: Telephone/crisis referral agency | C7: 2473 | D7: 2.2 | E7: 3786 | F7: 2.3 | G7: 6259 | H7: 2.3
A8: National | B8: Centrelink or employment service case worker | C8: 616 | D8: 0.6 | E8: 891 | F8: 0.5 | G8: 1507 | H8: 0.5
A9: National | B9: Child protection agency | C9: 1069 | D9: 1 | E9: 2370 | F9: 1.4 | G9: 3439 | H9: 1.2
A10: National | B10: Family and child support agency | C10: 1332 | D10: 1.2 | E10: 3029 | F10: 1.8 | G10: 4361 | H10: 1.6
A11: National | B11: Hospital | C11: 1710 | D11: 1.5 | E11: 3037 | F11: 1.8 | G11: 4747 | H11: 1.7
A12: National | B12: Mental health service | C12: 1122 | D12: 1 | E12: 1951 | F12: 1.2 | G12: 3073 | H12: 1.1
A13: National | B13: Disability support service | C13: 495 | D13: 0.4 | E13: 554 | F13: 0.3 | G13: 1049 | H13: 0.4
A14: National | B14: Drug and alcohol service | C14: 664 | D14: 0.6 | E14: 571 | F14: 0.3 | G14: 1235 | H14: 0.4
A15: National | B15: Aged care service | C15: 96 | D15: 0.1 | E15: 124 | F15: 0.1 | G15: 220 | H15: 0.1
A16: National | B16: Social housing | C16: 3522 | D16: 3.2 | E16: 4918 | F16: 3 | G16: 8440 | H16: 3
A17: National | B17: Youth/juvenile justice correctional centre | C17: 240 | D17: 0.2 | E17: 117 | F17: 0.1 | G17: 357 | H17: 0.1
... A28: National | B28: No formal referral | C28: 42024 | D28: 37.6 | E28: 57967 | F28: 35 | G28: 99991 | H28: 36
A29: National | B29: Not stated | C29: 1116 | D29: . . | E29: 1375 | F29: . . | G29: 2491 | H29: . .
A30: National | B30: Total | C30: 112873 | D30: 100 | E30: 167205 | F30: 100 | G30: 280078 | H30: 100
A31: NSW | B31: Specialist Homelessness Agency/outreach worker | C31: 4746 | D31: 17.5 | E31: 6352 | F31: 15.9 | G31: 11098 | H31: 16.5
A32: NSW | B32: Telephone/crisis referral agency | C32: 1121 | D32: 4.1 | E32: 1442 | F32: 3.6 | G32: 2563 | H32: 3.8
A33: NSW | B33: Centrelink or employment service case worker | C33: 165 | D33: 0.6 | E33: 263 | F33: 0.7 | G33: 428 | H33: 0.6
A34: NSW | B34: Child protection agency | C34: 297 | D34: 1.1 | E34: 652 | F34: 1.6 | G34: 949 | H34: 1.4
A35: NSW | B35: Family and child support agency | C35: 480 | D35: 1.8 | E35: 995 | F35: 2.5 | G35: 1475 | H35: 2.2
A36: NSW | B36: Hospital | C36: 392 | D36: 1.4 | E36: 590 | F36: 1.5 | G36: 982 | H36: 1.5
A37: NSW | B37: Mental health service | C37: 359 | D37: 1.3 | E37: 724 | F37: 1.8 | G37: 1083 | H37: 1.6
A38: NSW | B38: Disability support service | C38: 108 | D38: 0.4 | E38: 161 | F38: 0.4 | G38: 269 | H38: 0.4
A39: NSW | B39: Drug and alcohol service | C39: 202 | D39: 0.7 | E39: 206 | F39: 0.5 | G39: 408 | H39: 0.6
A40: NSW | B40: Aged care service | C40: 21 | D40: 0.1 | E40: 21 | F40: 0.1 | G40: 42 | H40: 0.1
A41: NSW | B41: Social housing | C41: 1415 | D41: 5.2 | E41: 1748 | F41: 4.4 | G41: 3163 | H41: 4.7
... A53: NSW | B53: No formal referral | C53: 8416 | D53: 31 | E53: 11572 | F53: 28.9 | G53: 19988 | H53: 29.8
A54: NSW | B54: Not stated | C54: 365 | D54: . . | E54: 419 | F54: . . | G54: 784 | H54: . .
A55: NSW | B55: Total | C55: 27486 | D55: 100 | E55: 40405 | F55: 100 | G55: 67891 | H55: 100
A56: Vic | B56: Specialist Homelessness Agency/outreach worker | C56: 7426 | D56: 17.7 | E56: 9793 | F56: 16.6 | G56: 17219 | H56: 17
A57: Vic | B57: Telephone/crisis referral agency | C57: 508 | D57: 1.2 | E57: 846 | F57: 1.4 | G57: 1354 | H57: 1.3
A58: Vic | B58: Centrelink or employment service case worker | C58: 94 | D58: 0.2 | E58: 113 | F58: 0.2 | G58: 207 | H58: 0.2
A59: Vic | B59: Child protection agency | C59: 231 | D59: 0.5 | E59: 473 | F59: 0.8 | G59: 704 | H59: 0.7
A60: Vic | B60: Family and child support agency | C60: 372 | D60: 0.9 | E60: 929 | F60: 1.6 | G60: 1301 | H60: 1.3
A61: Vic | B61: Hospital | C61: 410 | D61: 1 | E61: 466 | F61: 0.8 | G61: 876 | H61: 0.9
A62: Vic | B62: Mental health service | C62: 342 | D62: 0.8 | E62: 548 | F62: 0.9 | G62: 890 | H62: 0.9
...

Sheet CLIENTS.16
A1: Table of contents
A2: Table CLIENTS.16: Clients aged 15 and over, by main source of income, and by state and territory, 2023–24
C4: Males | D4: Males | E4: Females | F4: Females | G4: All clients | H4: All clients
A5: State/territory | B5: Main source of income | C5: Number | D5: Per cent | E5: Number | F5: Per cent | G5: Number | H5: Per cent
A6: National | B6: JobSeeker payment | C6: 28629 | D6: 38.3 | E6: 26686 | F6: 21.9 | G6: 55315 | H6: 28.2
A7: National | B7: Parenting payment | C7: 1848 | D7: 2.5 | E7: 31833 | F7: 26.2 | G7: 33681 | H7: 17.1
A8: National | B8: Disability support pension (Centrelink) | C8: 14452 | D8: 19.4 | E8: 14520 | F8: 11.9 | G8: 28972 | H8: 14.8
A9: National | B9: Youth allowance | C9: 4826 | D9: 6.5 | E9: 8030 | F9: 6.6 | G9: 12856 | H9: 6.5
A10: National | B10: Austudy/ABSTUDY | C10: 224 | D10: 0.3 | E10: 532 | F10: 0.4 | G10: 756 | H10: 0.4
A11: National | B11: Age pension | C11: 3132 | D11: 4.2 | E11: 3691 | F11: 3 | G11: 6823 | H11: 3.5
A12: National | B12: Sickness allowance | C12: 68 | D12: 0.1 | E12: 82 | F12: 0.1 | G12: 150 | H12: 0.1
A13: National | B13: Carer allowance | C13: 242 | D13: 0.3 | E13: 954 | F13: 0.8 | G13: 1196 | H13: 0.6
A14: National | B14: Carer Payment | C14: 802 | D14: 1.1 | E14: 3007 | F14: 2.5 | G14: 3809 | H14: 1.9
A15: National | B15: DVA pension or payment | C15: 225 | D15: 0.3 | E15: 164 | F15: 0.1 | G15: 389 | H15: 0.2
A16: National | B16: Other government pensions and allowances nec | C16: 764 | D16: 1 | E16: 2897 | F16: 2.4 | G16: 3661 | H16: 1.9
A17: National | B17: Employee income | C17: 7006 | D17: 9.4 | E17: 16788 | F17: 13.8 | G17: 23794 | H17: 12.1
... A21: National | B21: Nil income | C21: 9710 | D21: 13 | E21: 8973 | F21: 7.4 | G21: 18683 | H21: 9.5
A22: National | B22: Not stated | C22: 7454 | D22: . . | E22: 14949 | F22: . . | G22: 22403 | H22: . .
A23: National | B23: Total | C23: 82132 | D23: 100 | E23: 136668 | F23: 100 | G23: 218800 | H23: 100
A24: NSW | B24: JobSeeker payment | C24: 6834 | D24: 38.4 | E24: 5958 | F24: 19.9 | G24: 12792 | H24: 26.8
A25: NSW | B25: Parenting payment | C25: 402 | D25: 2.3 | E25: 7418 | F25: 24.8 | G25: 7820 | H25: 16.4
A26: NSW | B26: Disability support pension (Centrelink) | C26: 3435 | D26: 19.3 | E26: 3467 | F26: 11.6 | G26: 6902 | H26: 14.5
A27: NSW | B27: Youth allowance | C27: 1722 | D27: 9.7 | E27: 2752 | F27: 9.2 | G27: 4474 | H27: 9.4
A28: NSW | B28: Austudy/ABSTUDY | C28: 71 | D28: 0.4 | E28: 175 | F28: 0.6 | G28: 246 | H28: 0.5
A29: NSW | B29: Age pension | C29: 666 | D29: 3.7 | E29: 802 | F29: 2.7 | G29: 1468 | H29: 3.1
A30: NSW | B30: Sickness allowance | C30: 12 | D30: 0.1 | E30: 13 | F30: 0 | G30: 25 | H30: 0.1
A31: NSW | B31: Carer allowance | C31: 62 | D31: 0.3 | E31: 248 | F31: 0.8 | G31: 310 | H31: 0.6
A32: NSW | B32: Carer Payment | C32: 187 | D32: 1.1 | E32: 679 | F32: 2.3 | G32: 866 | H32: 1.8
A33: NSW | B33: DVA pension or payment | C33: 34 | D33: 0.2 | E33: 21 | F33: 0.1 | G33: 55 | H33: 0.1
A34: NSW | B34: Other government pensions and allowances nec | C34: 230 | D34: 1.3 | E34: 581 | F34: 1.9 | G34: 811 | H34: 1.7
... A39: NSW | B39: Nil income | C39: 1884 | D39: 10.6 | E39: 2713 | F39: 9.1 | G39: 4597 | H39: 9.6
A40: NSW | B40: Not stated | C40: 1800 | D40: . . | E40: 2346 | F40: . . | G40: 4146 | H40: . .
A41: NSW | B41: Total | C41: 19606 | D41: 100 | E41: 32289 | F41: 100 | G41: 51895 | H41: 100
A42: Vic | B42: JobSeeker payment | C42: 9536 | D42: 33.2 | E42: 8084 | F42: 19.6 | G42: 17620 | H42: 25.2
A43: Vic | B43: Parenting payment | C43: 672 | D43: 2.3 | E43: 9766 | F43: 23.7 | G43: 10438 | H43: 14.9
A44: Vic | B44: Disability support pension (Centrelink) | C44: 5582 | D44: 19.4 | E44: 5810 | F44: 14.1 | G44: 11392 | H44: 16.3
A45: Vic | B45: Youth allowance | C45: 1163 | D45: 4 | E45: 1831 | F45: 4.4 | G45: 2994 | H45: 4.3
A46: Vic | B46: Austudy/ABSTUDY | C46: 66 | D46: 0.2 | E46: 159 | F46: 0.4 | G46: 225 | H46: 0.3
A47: Vic | B47: Age pension | C47: 1286 | D47: 4.5 | E47: 1560 | F47: 3.8 | G47: 2846 | H47: 4.1
